[2023-06-24 14:52:44,869] {taskinstance.py:1159} INFO - Dependencies all met for <TaskInstance: 1_init_once_seed_data.load_seed_data_once manual__2023-06-24T14:52:43.872857+00:00 [queued]>
[2023-06-24 14:52:44,882] {taskinstance.py:1159} INFO - Dependencies all met for <TaskInstance: 1_init_once_seed_data.load_seed_data_once manual__2023-06-24T14:52:43.872857+00:00 [queued]>
[2023-06-24 14:52:44,883] {taskinstance.py:1356} INFO - 
--------------------------------------------------------------------------------
[2023-06-24 14:52:44,885] {taskinstance.py:1357} INFO - Starting attempt 1 of 1
[2023-06-24 14:52:44,886] {taskinstance.py:1358} INFO - 
--------------------------------------------------------------------------------
[2023-06-24 14:52:44,912] {taskinstance.py:1377} INFO - Executing <Task(BashOperator): load_seed_data_once> on 2023-06-24 14:52:43.872857+00:00
[2023-06-24 14:52:44,920] {standard_task_runner.py:52} INFO - Started process 232 to run task
[2023-06-24 14:52:44,926] {standard_task_runner.py:79} INFO - Running: ['***', 'tasks', 'run', '1_init_once_seed_data', 'load_seed_data_once', 'manual__2023-06-24T14:52:43.872857+00:00', '--job-id', '15', '--raw', '--subdir', 'DAGS_FOLDER/init.py', '--cfg-path', '/tmp/tmpuxclfmto', '--error-file', '/tmp/tmp3mfdz94v']
[2023-06-24 14:52:44,928] {standard_task_runner.py:80} INFO - Job 15: Subtask load_seed_data_once
[2023-06-24 14:52:45,008] {task_command.py:369} INFO - Running <TaskInstance: 1_init_once_seed_data.load_seed_data_once manual__2023-06-24T14:52:43.872857+00:00 [running]> on host eaf24e454131
[2023-06-24 14:52:45,142] {taskinstance.py:1571} INFO - Exporting the following env vars:
AIRFLOW_CTX_DAG_OWNER=***
AIRFLOW_CTX_DAG_ID=1_init_once_seed_data
AIRFLOW_CTX_TASK_ID=load_seed_data_once
AIRFLOW_CTX_EXECUTION_DATE=2023-06-24T14:52:43.872857+00:00
AIRFLOW_CTX_TRY_NUMBER=1
AIRFLOW_CTX_DAG_RUN_ID=manual__2023-06-24T14:52:43.872857+00:00
[2023-06-24 14:52:45,143] {subprocess.py:62} INFO - Tmp dir root location: 
 /tmp
[2023-06-24 14:52:45,145] {subprocess.py:74} INFO - Running command: ['bash', '-c', 'cd /dbt && dbt seed --profiles-dir .']
[2023-06-24 14:52:45,161] {subprocess.py:85} INFO - Output:
[2023-06-24 14:52:45,165] {subprocess.py:92} INFO - bash: line 1: dbt: command not found
[2023-06-24 14:52:45,166] {subprocess.py:96} INFO - Command exited with return code 127
[2023-06-24 14:52:45,187] {taskinstance.py:1889} ERROR - Task failed with exception
Traceback (most recent call last):
  File "/home/airflow/.local/lib/python3.7/site-packages/airflow/operators/bash.py", line 195, in execute
    f'Bash command failed. The command returned a non-zero exit code {result.exit_code}.'
airflow.exceptions.AirflowException: Bash command failed. The command returned a non-zero exit code 127.
[2023-06-24 14:52:45,191] {taskinstance.py:1400} INFO - Marking task as FAILED. dag_id=1_init_once_seed_data, task_id=load_seed_data_once, execution_date=20230624T145243, start_date=20230624T145244, end_date=20230624T145245
[2023-06-24 14:52:45,216] {standard_task_runner.py:97} ERROR - Failed to execute job 15 for task load_seed_data_once (Bash command failed. The command returned a non-zero exit code 127.; 232)
[2023-06-24 14:52:45,261] {local_task_job.py:156} INFO - Task exited with return code 1
[2023-06-24 14:52:45,326] {local_task_job.py:273} INFO - 0 downstream tasks scheduled from follow-on schedule check
