[2023-06-24 15:18:01,419] {taskinstance.py:1159} INFO - Dependencies all met for <TaskInstance: 1_init_once_seed_data.load_seed_data_once manual__2023-06-24T15:18:00.502851+00:00 [queued]>
[2023-06-24 15:18:01,438] {taskinstance.py:1159} INFO - Dependencies all met for <TaskInstance: 1_init_once_seed_data.load_seed_data_once manual__2023-06-24T15:18:00.502851+00:00 [queued]>
[2023-06-24 15:18:01,439] {taskinstance.py:1356} INFO - 
--------------------------------------------------------------------------------
[2023-06-24 15:18:01,442] {taskinstance.py:1357} INFO - Starting attempt 1 of 1
[2023-06-24 15:18:01,443] {taskinstance.py:1358} INFO - 
--------------------------------------------------------------------------------
[2023-06-24 15:18:01,473] {taskinstance.py:1377} INFO - Executing <Task(BashOperator): load_seed_data_once> on 2023-06-24 15:18:00.502851+00:00
[2023-06-24 15:18:01,488] {standard_task_runner.py:52} INFO - Started process 590 to run task
[2023-06-24 15:18:01,498] {standard_task_runner.py:79} INFO - Running: ['***', 'tasks', 'run', '1_init_once_seed_data', 'load_seed_data_once', 'manual__2023-06-24T15:18:00.502851+00:00', '--job-id', '22', '--raw', '--subdir', 'DAGS_FOLDER/init.py', '--cfg-path', '/tmp/tmppcusgwaj', '--error-file', '/tmp/tmpvekeqp5s']
[2023-06-24 15:18:01,499] {standard_task_runner.py:80} INFO - Job 22: Subtask load_seed_data_once
[2023-06-24 15:18:01,606] {task_command.py:369} INFO - Running <TaskInstance: 1_init_once_seed_data.load_seed_data_once manual__2023-06-24T15:18:00.502851+00:00 [running]> on host e468c72596db
[2023-06-24 15:18:01,785] {taskinstance.py:1571} INFO - Exporting the following env vars:
AIRFLOW_CTX_DAG_OWNER=***
AIRFLOW_CTX_DAG_ID=1_init_once_seed_data
AIRFLOW_CTX_TASK_ID=load_seed_data_once
AIRFLOW_CTX_EXECUTION_DATE=2023-06-24T15:18:00.502851+00:00
AIRFLOW_CTX_TRY_NUMBER=1
AIRFLOW_CTX_DAG_RUN_ID=manual__2023-06-24T15:18:00.502851+00:00
[2023-06-24 15:18:01,788] {subprocess.py:62} INFO - Tmp dir root location: 
 /tmp
[2023-06-24 15:18:01,790] {subprocess.py:74} INFO - Running command: ['bash', '-c', 'cd /dbt && dbt seed --profiles-dir .']
[2023-06-24 15:18:01,807] {subprocess.py:85} INFO - Output:
[2023-06-24 15:18:03,812] {subprocess.py:92} INFO - Running with dbt=0.19.0
[2023-06-24 15:18:10,662] {subprocess.py:92} INFO - Found 7 models, 4 tests, 0 snapshots, 0 analyses, 316 macros, 0 operations, 3 seed files, 0 sources, 0 exposures
[2023-06-24 15:18:10,664] {subprocess.py:92} INFO - 
[2023-06-24 15:20:32,115] {subprocess.py:92} INFO - Encountered an error:
[2023-06-24 15:20:32,117] {subprocess.py:92} INFO - Runtime Error
[2023-06-24 15:20:32,118] {subprocess.py:92} INFO -   Database error while listing schemas in database "demo_dbt"
[2023-06-24 15:20:32,119] {subprocess.py:92} INFO -   Database Error
[2023-06-24 15:20:32,119] {subprocess.py:92} INFO -     250003: Failed to execute request: HTTPSConnectionPool(host='https', port=443): Max retries exceeded with url: //fq75734.us-east-2.aws.snowflakecomputing.com:443/session/v1/login-request?request_id=a2cd0b80-e947-4067-b91a-724b819b9068&databaseName=demo_dbt&schemaName=public&warehouse=dbt_dev_wh&roleName=dbt_dev_role (Caused by NewConnectionError('<urllib3.connection.HTTPSConnection object at 0x7fbacc3709d0>: Failed to establish a new connection: [Errno -5] No address associated with hostname'))
[2023-06-24 15:20:32,492] {subprocess.py:96} INFO - Command exited with return code 2
[2023-06-24 15:20:32,523] {taskinstance.py:1889} ERROR - Task failed with exception
Traceback (most recent call last):
  File "/home/airflow/.local/lib/python3.7/site-packages/airflow/operators/bash.py", line 195, in execute
    f'Bash command failed. The command returned a non-zero exit code {result.exit_code}.'
airflow.exceptions.AirflowException: Bash command failed. The command returned a non-zero exit code 2.
[2023-06-24 15:20:32,530] {taskinstance.py:1400} INFO - Marking task as FAILED. dag_id=1_init_once_seed_data, task_id=load_seed_data_once, execution_date=20230624T151800, start_date=20230624T151801, end_date=20230624T152032
[2023-06-24 15:20:32,555] {standard_task_runner.py:97} ERROR - Failed to execute job 22 for task load_seed_data_once (Bash command failed. The command returned a non-zero exit code 2.; 590)
[2023-06-24 15:20:32,598] {local_task_job.py:156} INFO - Task exited with return code 1
[2023-06-24 15:20:32,672] {local_task_job.py:273} INFO - 0 downstream tasks scheduled from follow-on schedule check
