[2023-06-24 14:57:54,549] {taskinstance.py:1159} INFO - Dependencies all met for <TaskInstance: 1_init_once_seed_data.load_seed_data_once manual__2023-06-24T14:57:52.994029+00:00 [queued]>
[2023-06-24 14:57:54,560] {taskinstance.py:1159} INFO - Dependencies all met for <TaskInstance: 1_init_once_seed_data.load_seed_data_once manual__2023-06-24T14:57:52.994029+00:00 [queued]>
[2023-06-24 14:57:54,562] {taskinstance.py:1356} INFO - 
--------------------------------------------------------------------------------
[2023-06-24 14:57:54,564] {taskinstance.py:1357} INFO - Starting attempt 1 of 1
[2023-06-24 14:57:54,565] {taskinstance.py:1358} INFO - 
--------------------------------------------------------------------------------
[2023-06-24 14:57:54,589] {taskinstance.py:1377} INFO - Executing <Task(BashOperator): load_seed_data_once> on 2023-06-24 14:57:52.994029+00:00
[2023-06-24 14:57:54,598] {standard_task_runner.py:52} INFO - Started process 100 to run task
[2023-06-24 14:57:54,605] {standard_task_runner.py:79} INFO - Running: ['***', 'tasks', 'run', '1_init_once_seed_data', 'load_seed_data_once', 'manual__2023-06-24T14:57:52.994029+00:00', '--job-id', '18', '--raw', '--subdir', 'DAGS_FOLDER/init.py', '--cfg-path', '/tmp/tmpq6bi3hx9', '--error-file', '/tmp/tmp146nc92v']
[2023-06-24 14:57:54,606] {standard_task_runner.py:80} INFO - Job 18: Subtask load_seed_data_once
[2023-06-24 14:57:54,702] {task_command.py:369} INFO - Running <TaskInstance: 1_init_once_seed_data.load_seed_data_once manual__2023-06-24T14:57:52.994029+00:00 [running]> on host ec09f6d2d243
[2023-06-24 14:57:54,866] {taskinstance.py:1571} INFO - Exporting the following env vars:
AIRFLOW_CTX_DAG_OWNER=***
AIRFLOW_CTX_DAG_ID=1_init_once_seed_data
AIRFLOW_CTX_TASK_ID=load_seed_data_once
AIRFLOW_CTX_EXECUTION_DATE=2023-06-24T14:57:52.994029+00:00
AIRFLOW_CTX_TRY_NUMBER=1
AIRFLOW_CTX_DAG_RUN_ID=manual__2023-06-24T14:57:52.994029+00:00
[2023-06-24 14:57:54,870] {subprocess.py:62} INFO - Tmp dir root location: 
 /tmp
[2023-06-24 14:57:54,871] {subprocess.py:74} INFO - Running command: ['bash', '-c', 'cd /dbt && dbt seed --profiles-dir .']
[2023-06-24 14:57:54,885] {subprocess.py:85} INFO - Output:
[2023-06-24 14:57:54,891] {subprocess.py:92} INFO - bash: line 1: dbt: command not found
[2023-06-24 14:57:54,892] {subprocess.py:96} INFO - Command exited with return code 127
[2023-06-24 14:57:54,924] {taskinstance.py:1889} ERROR - Task failed with exception
Traceback (most recent call last):
  File "/home/airflow/.local/lib/python3.7/site-packages/airflow/operators/bash.py", line 195, in execute
    f'Bash command failed. The command returned a non-zero exit code {result.exit_code}.'
airflow.exceptions.AirflowException: Bash command failed. The command returned a non-zero exit code 127.
[2023-06-24 14:57:54,933] {taskinstance.py:1400} INFO - Marking task as FAILED. dag_id=1_init_once_seed_data, task_id=load_seed_data_once, execution_date=20230624T145752, start_date=20230624T145754, end_date=20230624T145754
[2023-06-24 14:57:54,955] {standard_task_runner.py:97} ERROR - Failed to execute job 18 for task load_seed_data_once (Bash command failed. The command returned a non-zero exit code 127.; 100)
[2023-06-24 14:57:55,062] {local_task_job.py:156} INFO - Task exited with return code 1
[2023-06-24 14:57:55,114] {local_task_job.py:273} INFO - 0 downstream tasks scheduled from follow-on schedule check
