[2023-06-24 13:59:02,537] {taskinstance.py:1159} INFO - Dependencies all met for <TaskInstance: 1_init_once_seed_data.load_seed_data_once scheduled__2020-08-01T00:00:00+00:00 [queued]>
[2023-06-24 13:59:02,552] {taskinstance.py:1159} INFO - Dependencies all met for <TaskInstance: 1_init_once_seed_data.load_seed_data_once scheduled__2020-08-01T00:00:00+00:00 [queued]>
[2023-06-24 13:59:02,552] {taskinstance.py:1356} INFO - 
--------------------------------------------------------------------------------
[2023-06-24 13:59:02,553] {taskinstance.py:1357} INFO - Starting attempt 1 of 1
[2023-06-24 13:59:02,554] {taskinstance.py:1358} INFO - 
--------------------------------------------------------------------------------
[2023-06-24 13:59:02,569] {taskinstance.py:1377} INFO - Executing <Task(BashOperator): load_seed_data_once> on 2020-08-01 00:00:00+00:00
[2023-06-24 13:59:02,579] {standard_task_runner.py:52} INFO - Started process 392 to run task
[2023-06-24 13:59:02,582] {standard_task_runner.py:79} INFO - Running: ['***', 'tasks', 'run', '1_init_once_seed_data', 'load_seed_data_once', 'scheduled__2020-08-01T00:00:00+00:00', '--job-id', '4', '--raw', '--subdir', 'DAGS_FOLDER/init.py', '--cfg-path', '/tmp/tmp0x66yk1z', '--error-file', '/tmp/tmpdgicmxz3']
[2023-06-24 13:59:02,583] {standard_task_runner.py:80} INFO - Job 4: Subtask load_seed_data_once
[2023-06-24 13:59:02,633] {task_command.py:369} INFO - Running <TaskInstance: 1_init_once_seed_data.load_seed_data_once scheduled__2020-08-01T00:00:00+00:00 [running]> on host 8b5fcfa38f31
[2023-06-24 13:59:02,740] {taskinstance.py:1571} INFO - Exporting the following env vars:
AIRFLOW_CTX_DAG_OWNER=***
AIRFLOW_CTX_DAG_ID=1_init_once_seed_data
AIRFLOW_CTX_TASK_ID=load_seed_data_once
AIRFLOW_CTX_EXECUTION_DATE=2020-08-01T00:00:00+00:00
AIRFLOW_CTX_TRY_NUMBER=1
AIRFLOW_CTX_DAG_RUN_ID=scheduled__2020-08-01T00:00:00+00:00
[2023-06-24 13:59:02,742] {subprocess.py:62} INFO - Tmp dir root location: 
 /tmp
[2023-06-24 13:59:02,743] {subprocess.py:74} INFO - Running command: ['bash', '-c', 'cd /dbt && dbt seed --profiles-dir .']
[2023-06-24 13:59:02,758] {subprocess.py:85} INFO - Output:
[2023-06-24 13:59:02,760] {subprocess.py:92} INFO - bash: line 1: dbt: command not found
[2023-06-24 13:59:02,761] {subprocess.py:96} INFO - Command exited with return code 127
[2023-06-24 13:59:02,779] {taskinstance.py:1889} ERROR - Task failed with exception
Traceback (most recent call last):
  File "/home/airflow/.local/lib/python3.7/site-packages/airflow/operators/bash.py", line 195, in execute
    f'Bash command failed. The command returned a non-zero exit code {result.exit_code}.'
airflow.exceptions.AirflowException: Bash command failed. The command returned a non-zero exit code 127.
[2023-06-24 13:59:02,783] {taskinstance.py:1400} INFO - Marking task as FAILED. dag_id=1_init_once_seed_data, task_id=load_seed_data_once, execution_date=20200801T000000, start_date=20230624T135902, end_date=20230624T135902
[2023-06-24 13:59:02,796] {standard_task_runner.py:97} ERROR - Failed to execute job 4 for task load_seed_data_once (Bash command failed. The command returned a non-zero exit code 127.; 392)
[2023-06-24 13:59:02,837] {local_task_job.py:156} INFO - Task exited with return code 1
[2023-06-24 13:59:02,878] {local_task_job.py:273} INFO - 0 downstream tasks scheduled from follow-on schedule check
